<?xml version="1.0" ?>
<!-- =================================================================================== -->
<!-- |    This document was autogenerated by xacro from aero_base.urdf.xacro           | -->
<!-- |    EDITING THIS FILE BY HAND IS NOT RECOMMENDED                                 | -->
<!-- =================================================================================== -->
<robot name="aero" xmlns:body="http://playerstage.sourceforge.net/gazebo/xmlschema/#body" xmlns:controller="http://playerstage.sourceforge.net/gazebo/xmlschema/#controller" xmlns:gazebo="http://playerstage.sourceforge.net/gazebo/xmlschema/#gz" xmlns:geom="http://playerstage.sourceforge.net/gazebo/xmlschema/#geom" xmlns:interface="http://playerstage.sourceforge.net/gazebo/xmlschema/#interface" xmlns:joint="http://playerstage.sourceforge.net/gazebo/xmlschema/#joint" xmlns:model="http://playerstage.sourceforge.net/gazebo/xmlschema/#model" xmlns:physics="http://playerstage.sourceforge.net/gazebo/xmlschema/#physics" xmlns:renderable="http://playerstage.sourceforge.net/gazebo/xmlschema/#renderable" xmlns:rendering="http://playerstage.sourceforge.net/gazebo/xmlschema/#rendering" xmlns:sensor="http://playerstage.sourceforge.net/gazebo/xmlschema/#sensor" xmlns:xacro="http://ros.org/wiki/xacro" xmlns:xi="http://www.w3.org/2001/XInclude">
  <!-- Included URDF/XACRO Files -->
  <gazebo>
    <plugin filename="libgazebo_ros_control.so" name="gazebo_ros_control">
      <robotNamespace>/aero</robotNamespace>
      <robotSimType>aero_gazebo/AeroHWSim</robotSimType>
    </plugin>
  </gazebo>
  <material name="Black">
    <color rgba="0.0 0.0 0.0 1.0"/>
  </material>
  <material name="Blue">
    <color rgba="0.0 0.0 0.8 1.0"/>
  </material>
  <material name="Green">
    <color rgba="0.0 0.8 0.0 1.0"/>
  </material>
  <material name="Gray">
    <color rgba="0.7 0.7 0.7 1.0"/>
  </material>
  <material name="DarkGray">
    <color rgba="0.3 0.3 0.3 1.0"/>
  </material>
  <material name="Red">
    <color rgba="0.8 0.0 0.0 1.0"/>
  </material>
  <material name="White">
    <color rgba="1.0 1.0 1.0 1.0"/>
  </material>
  <material name="Yellow">
    <color rgba="0.8 0.8 0.0 1.0"/>
  </material>
  <link name="aero/base_footprint">
    <visual>
      <origin rpy="0 0 0" xyz="0 0 0"/>
      <geometry>
        <box size="0.001 0.001 0.001"/>
      </geometry>
    </visual>
  </link>
  <gazebo reference="aero/base_footprint">
    <turnGravityOff>false</turnGravityOff>
  </gazebo>
  <joint name="aero/base_footprint_joint" type="fixed">
    <origin rpy="0 0 0" xyz="0 0 0.14492492"/>
    <parent link="aero/base_footprint"/>
    <child link="aero/base_link"/>
  </joint>
  <link name="aero/base_link">
    <inertial>
      <mass value="70.45489"/>
      <!--This is the pose of the inertial reference frame, relative to the link reference frame. The origin of the inertial reference frame needs to be at the center of gravity. The axes of the inertial reference frame do not need to be aligned with the principal axes of the inertia.-->
      <origin xyz="-0.08748 -0.00085 0.09947"/>
      <!--The 3x3 rotational inertia matrix. Because the rotational inertia matrix is symmetric, only 6 above-diagonal elements of this matrix are specified here, using the attributes ixx, ixy, ixz, iyy, iyz, izz.-->
      <inertia ixx="0.6021637" ixy="-0.02364198" ixz="-0.11972132" iyy="1.73859574" iyz="-0.00154437" izz="2.02955229"/>
    </inertial>
    <visual>
      <origin rpy="0 0 0" xyz="0 0 0"/>
      <geometry>
        <mesh filename="package://husky_description/meshes/base_link.stl"/>
      </geometry>
      <material name="Black"/>
    </visual>
    <collision>
      <origin rpy="1.57079632679 0 1.57079632679" xyz="-0.40 -0.203 0"/>
      <geometry>
        <mesh filename="package://aero_description/meshes/base_collision.dae"/>
      </geometry>
      <material name="Black"/>
    </collision>
  </link>
  <gazebo reference="aero/base_link">
    <material>Gazebo/FlatBlack</material>
    <turnGravityOff>false</turnGravityOff>
  </gazebo>
  <link name="aero/back_left_wheel">
    <inertial>
      <mass value="2.63657"/>
      <origin xyz="0.0 0.0 0.00019"/>
      <inertia ixx="0.02466885" ixy="0.0" ixz="0.0" iyy="0.02466885" iyz="0.0" izz="0.04410576"/>
    </inertial>
    <visual>
      <origin rpy="-3.14159265359 0 0" xyz="0 0 0"/>
      <geometry>
        <mesh filename="package://husky_description/meshes/wheel.stl"/>
      </geometry>
      <material name="DarkGray"/>
    </visual>
    <collision>
      <origin rpy="-1.57079632679 0 0" xyz="0 0 0"/>
      <geometry>
        <cylinder length="0.1143" radius="0.17775"/>
      </geometry>
    </collision>
  </link>
  <gazebo reference="aero/back_left_wheel">
    <mu1 value="0.7"/>
    <mu2 value="0.6"/>
    <kp value="10000000.0"/>
    <kd value="1.0"/>
    <fdir1 value="1 0 0"/>
    <material>Gazebo/Grey</material>
    <turnGravityOff>false</turnGravityOff>
  </gazebo>
  <joint name="aero/joint_back_left_wheel" type="continuous">
    <parent link="aero/base_link"/>
    <child link="aero/back_left_wheel"/>
    <origin rpy="0 0 0" xyz="-0.25600006 0.285475 0.03282508"/>
    <axis rpy="0 0 0" xyz="0 1 0"/>
    <limit effort="100" velocity="100"/>
    <joint_properties damping="0.0" friction="0.0"/>
    <mimic joint="aero/joint_front_left_wheel" multiplier="1.0" offset="0.0"/>
  </joint>
  <transmission name="aero/back_left_wheel_tran">
    <type>transmission_interface/SimpleTransmission</type>
    <joint name="aero/joint_back_left_wheel"/>
    <actuator name="aero/left_wheel_motor">
      <hardwareInterface>VelocityJointInterface</hardwareInterface>
      <mechanicalReduction>-15</mechanicalReduction>
    </actuator>
  </transmission>
  <link name="aero/back_right_wheel">
    <inertial>
      <mass value="2.63657"/>
      <origin xyz="0.0 0.0 0.00019"/>
      <inertia ixx="0.02466885" ixy="0.0" ixz="0.0" iyy="0.02466885" iyz="0.0" izz="0.04410576"/>
    </inertial>
    <visual>
      <origin rpy="-3.14159265359 0 0" xyz="0 0 0"/>
      <geometry>
        <mesh filename="package://husky_description/meshes/wheel.stl"/>
      </geometry>
      <material name="DarkGray"/>
    </visual>
    <collision>
      <origin rpy="-1.57079632679 0 0" xyz="0 0 0"/>
      <geometry>
        <cylinder length="0.1143" radius="0.17775"/>
      </geometry>
    </collision>
  </link>
  <gazebo reference="aero/back_right_wheel">
    <mu1 value="0.7"/>
    <mu2 value="0.6"/>
    <kp value="10000000.0"/>
    <kd value="1.0"/>
    <fdir1 value="1 0 0"/>
    <material>Gazebo/Grey</material>
    <turnGravityOff>false</turnGravityOff>
  </gazebo>
  <joint name="aero/joint_back_right_wheel" type="continuous">
    <parent link="aero/base_link"/>
    <child link="aero/back_right_wheel"/>
    <origin rpy="0 0 0" xyz="-0.25600006 -0.285475 0.03282508"/>
    <axis rpy="0 0 0" xyz="0 1 0"/>
    <limit effort="100" velocity="100"/>
    <joint_properties damping="0.0" friction="0.0"/>
    <mimic joint="aero/joint_front_right_wheel" multiplier="1.0" offset="0.0"/>
  </joint>
  <transmission name="aero/back_right_wheel_tran">
    <type>transmission_interface/SimpleTransmission</type>
    <joint name="aero/joint_back_right_wheel"/>
    <actuator name="aero/right_wheel_motor">
      <hardwareInterface>VelocityJointInterface</hardwareInterface>
      <mechanicalReduction>-15</mechanicalReduction>
    </actuator>
  </transmission>
  <link name="aero/front_left_wheel">
    <inertial>
      <mass value="2.63657"/>
      <origin xyz="0.0 0.0 0.00019"/>
      <inertia ixx="0.02466885" ixy="0.0" ixz="0.0" iyy="0.02466885" iyz="0.0" izz="0.04410576"/>
    </inertial>
    <visual>
      <origin rpy="-3.14159265359 0 0" xyz="0 0 0"/>
      <geometry>
        <mesh filename="package://husky_description/meshes/wheel.stl"/>
      </geometry>
      <material name="DarkGray"/>
    </visual>
    <collision>
      <origin rpy="-1.57079632679 0 0" xyz="0 0 0"/>
      <geometry>
        <cylinder length="0.1143" radius="0.17775"/>
      </geometry>
    </collision>
  </link>
  <gazebo reference="aero/front_left_wheel">
    <mu1 value="0.7"/>
    <mu2 value="0.6"/>
    <kp value="10000000.0"/>
    <kd value="1.0"/>
    <fdir1 value="1 0 0"/>
    <material>Gazebo/Grey</material>
    <turnGravityOff>false</turnGravityOff>
  </gazebo>
  <joint name="aero/joint_front_left_wheel" type="continuous">
    <parent link="aero/base_link"/>
    <child link="aero/front_left_wheel"/>
    <origin rpy="0 0 0" xyz="0.25600006 0.285475 0.03282508"/>
    <axis rpy="0 0 0" xyz="0 1 0"/>
    <limit effort="100" velocity="100"/>
    <joint_properties damping="0.0" friction="0.0"/>
  </joint>
  <transmission name="aero/front_left_wheel_tran">
    <type>transmission_interface/SimpleTransmission</type>
    <joint name="aero/joint_front_left_wheel"/>
    <actuator name="aero/left_wheel_motor">
      <hardwareInterface>VelocityJointInterface</hardwareInterface>
      <mechanicalReduction>-15</mechanicalReduction>
    </actuator>
  </transmission>
  <link name="aero/front_right_wheel">
    <inertial>
      <mass value="2.63657"/>
      <origin xyz="0.0 0.0 0.00019"/>
      <inertia ixx="0.02466885" ixy="0.0" ixz="0.0" iyy="0.02466885" iyz="0.0" izz="0.04410576"/>
    </inertial>
    <visual>
      <origin rpy="-3.14159265359 0 0" xyz="0 0 0"/>
      <geometry>
        <mesh filename="package://husky_description/meshes/wheel.stl"/>
      </geometry>
      <material name="DarkGray"/>
    </visual>
    <collision>
      <origin rpy="-1.57079632679 0 0" xyz="0 0 0"/>
      <geometry>
        <cylinder length="0.1143" radius="0.17775"/>
      </geometry>
    </collision>
  </link>
  <gazebo reference="aero/front_right_wheel">
    <mu1 value="0.7"/>
    <mu2 value="0.6"/>
    <kp value="10000000.0"/>
    <kd value="1.0"/>
    <fdir1 value="1 0 0"/>
    <material>Gazebo/Grey</material>
    <turnGravityOff>false</turnGravityOff>
  </gazebo>
  <joint name="aero/joint_front_right_wheel" type="continuous">
    <parent link="aero/base_link"/>
    <child link="aero/front_right_wheel"/>
    <origin rpy="0 0 0" xyz="0.25600006 -0.285475 0.03282508"/>
    <axis rpy="0 0 0" xyz="0 1 0"/>
    <limit effort="100" velocity="100"/>
    <joint_properties damping="0.0" friction="0.0"/>
  </joint>
  <transmission name="aero/front_right_wheel_tran">
    <type>transmission_interface/SimpleTransmission</type>
    <joint name="aero/joint_front_right_wheel"/>
    <actuator name="aero/right_wheel_motor">
      <hardwareInterface>VelocityJointInterface</hardwareInterface>
      <mechanicalReduction>-15</mechanicalReduction>
    </actuator>
  </transmission>
  <link name="aero/base_footprint_top_plate_part">
    <inertial>
      <mass value="0.1"/>
      <origin xyz="0.0 0.0 0.0"/>
      <inertia ixx="0.01" ixy="0.0" ixz="0.0" iyy="0.01" iyz="0.0" izz="0.01"/>
    </inertial>
    <visual>
      <origin rpy="0 0 0" xyz="0 0 0"/>
      <geometry>
        <mesh filename="package://husky_description/meshes/top_plate.stl"/>
      </geometry>
      <material name="Yellow"/>
    </visual>
    <collision>
      <origin rpy="0 0 0" xyz="0 0 0"/>
      <geometry>
        <box size="0.001 0.001 0.001"/>
        <!--the collision boundary for parts are taken into account by collision boundary of the base_link-->
      </geometry>
    </collision>
  </link>
  <joint name="aero/base_footprint_top_plate_joint" type="fixed">
    <origin rpy="0.0 0.0 0.0" xyz="0.0 0.0 0.14492492"/>
    <parent link="aero/base_footprint"/>
    <child link="aero/base_footprint_top_plate_part"/>
  </joint>
  <gazebo reference="aero/base_footprint_top_plate_part">
    <material>Gazebo/Yellow</material>
  </gazebo>
  <link name="aero/base_footprint_user_rail_part">
    <inertial>
      <mass value="0.1"/>
      <origin xyz="0.0 0.0 0.0"/>
      <inertia ixx="0.01" ixy="0.0" ixz="0.0" iyy="0.01" iyz="0.0" izz="0.01"/>
    </inertial>
    <visual>
      <origin rpy="0 0 0" xyz="0 0 0"/>
      <geometry>
        <mesh filename="package://husky_description/meshes/user_rail.stl"/>
      </geometry>
      <material name="DarkGray"/>
    </visual>
    <collision>
      <origin rpy="0 0 0" xyz="0 0 0"/>
      <geometry>
        <box size="0.001 0.001 0.001"/>
        <!--the collision boundary for parts are taken into account by collision boundary of the base_link-->
      </geometry>
    </collision>
  </link>
  <joint name="aero/base_footprint_user_rail_joint" type="fixed">
    <origin rpy="0.0 0.0 0.0" xyz="0.272 0.0 0.38992492"/>
    <parent link="aero/base_footprint"/>
    <child link="aero/base_footprint_user_rail_part"/>
  </joint>
  <gazebo reference="base_footprint_user_rail_part">
    <material>Gazebo/Grey</material>
  </gazebo>
  <link name="aero/base_footprint_front_bumper_part">
    <inertial>
      <mass value="0.1"/>
      <origin xyz="0.0 0.0 0.0"/>
      <inertia ixx="0.01" ixy="0.0" ixz="0.0" iyy="0.01" iyz="0.0" izz="0.01"/>
    </inertial>
    <visual>
      <origin rpy="0 0 0" xyz="0 0 0"/>
      <geometry>
        <mesh filename="package://husky_description/meshes/bumper.stl"/>
      </geometry>
      <material name="DarkGray"/>
    </visual>
    <collision>
      <origin rpy="0 0 0" xyz="0 0 0"/>
      <geometry>
        <box size="0.001 0.001 0.001"/>
        <!--the collision boundary for parts are taken into account by collision boundary of the base_link-->
      </geometry>
    </collision>
  </link>
  <joint name="aero/base_footprint_front_bumper_joint" type="fixed">
    <origin rpy="0.0 0.0 0.0" xyz="0.49 0.0 0.23592492"/>
    <parent link="aero/base_footprint"/>
    <child link="aero/base_footprint_front_bumper_part"/>
  </joint>
  <gazebo reference="aero/base_footprint_front_bumper_part">
    <material>Gazebo/FlatBlack</material>
  </gazebo>
  <link name="aero/base_footprint_rear_bumper_part">
    <inertial>
      <mass value="0.1"/>
      <origin xyz="0.0 0.0 0.0"/>
      <inertia ixx="0.01" ixy="0.0" ixz="0.0" iyy="0.01" iyz="0.0" izz="0.01"/>
    </inertial>
    <visual>
      <origin rpy="0 0 0" xyz="0 0 0"/>
      <geometry>
        <mesh filename="package://husky_description/meshes/bumper.stl"/>
      </geometry>
      <material name="DarkGray"/>
    </visual>
    <collision>
      <origin rpy="0 0 0" xyz="0 0 0"/>
      <geometry>
        <box size="0.001 0.001 0.001"/>
        <!--the collision boundary for parts are taken into account by collision boundary of the base_link-->
      </geometry>
    </collision>
  </link>
  <joint name="aero/base_footprint_rear_bumper_joint" type="fixed">
    <origin rpy="0.0 0.0 3.14" xyz="-0.48 0.0 0.23592492"/>
    <parent link="aero/base_footprint"/>
    <child link="aero/base_footprint_rear_bumper_part"/>
  </joint>
  <gazebo reference="aero/base_footprint_rear_bumper_part">
    <material>Gazebo/FlatBlack</material>
  </gazebo>
  <!-- Laser -->
  <joint name="aero/laser_joint" type="fixed">
    <axis xyz="0 1 0"/>
    <origin rpy="3.14159265359 0 0" xyz="0.4587 0 0.16"/>
    <parent link="aero/base_link"/>
    <child link="aero/laser_link"/>
  </joint>
  <link name="aero/laser_link">
    <inertial>
      <mass value="0.001"/>
      <origin rpy="0 0 0" xyz="0 0 0"/>
      <inertia ixx="0.0001" ixy="0" ixz="0" iyy="0.000001" iyz="0" izz="0.0001"/>
    </inertial>
    <visual>
      <origin rpy="0 0 0" xyz="0.0 0.0 0"/>
      <geometry>
        <mesh filename="package://aero_description/meshes/LMS151.STL"/>
      </geometry>
    </visual>
    <!--
      <collision>
      <origin xyz="0 0 0" rpy="0 0 0" />
      <geometry>
        <mesh filename="package://aero_description/meshes/LMS151.STL"/>
      </geometry>             
    </collision>
    -->
  </link>
  <gazebo reference="aero/laser_link">
    <sensor name="aero/laser_sensor" type="gpu_ray">
      <pose>0 0 0 0 0 0</pose>
      <visualize>false</visualize>
      <update_rate>25</update_rate>
      <ray>
        <scan>
          <horizontal>
            <samples>640</samples>
            <resolution>1</resolution>
            <min_angle>-2.35619</min_angle>
            <max_angle>2.35619</max_angle>
          </horizontal>
        </scan>
        <range>
          <min>0.5</min>
          <max>50.0</max>
          <resolution>0.01</resolution>
        </range>
        <noise>
          <type>gaussian</type>
          <mean>0.0</mean>
          <stddev>0.01</stddev>
        </noise>
      </ray>
      <plugin filename="libgazebo_ros_gpu_laser.so" name="gazebo_ros_head_hokuyo_controller">
        <topicName>/aero/laser</topicName>
        <frameName>aero/laser_link</frameName>
      </plugin>
    </sensor>
  </gazebo>
  <!-- Camera Boom -->
  <link name="aero/boom">
    <visual>
      <origin rpy="0 0 0" xyz="0.0 0.0 0.5425"/>
      <geometry>
        <cylinder length="1.085" radius="0.0269"/>
      </geometry>
      <material name="Black"/>
    </visual>
    <collision>
      <origin rpy="0 0 0" xyz="0.0 0.0 0.5425"/>
      <geometry>
        <cylinder length="1.085" radius="0.0269"/>
      </geometry>
    </collision>
    <inertial>
      <origin rpy="0 0 0" xyz="0 0 0"/>
      <mass value="1"/>
      <inertia ixx="1.0" ixy="0.0" ixz="0.0" iyy="1.0" iyz="0.0" izz="1.0"/>
    </inertial>
  </link>
  <joint name="aero/boom_joint" type="revolute">
    <parent link="aero/boom_base"/>
    <child link="aero/boom"/>
    <origin rpy="0 0 0" xyz="0 0 0"/>
    <axis xyz="0 0 1"/>
    <limit effort="1000" lower="-2" upper="2" velocity="6"/>
  </joint>
  <link name="aero/boom_top">
    <visual>
      <origin rpy="0 0 0" xyz="0 0 0"/>
      <geometry>
        <box size="0.00 0.00 0.00"/>
      </geometry>
    </visual>
    <collision>
      <origin rpy="0 0 0" xyz="0 0 0"/>
      <geometry>
        <box size="0.00 0.00 0.00"/>
      </geometry>
    </collision>
    <inertial>
      <origin rpy="0 0 0" xyz="0 0 0"/>
      <mass value="1"/>
      <inertia ixx="1.0" ixy="0.0" ixz="0.0" iyy="1.0" iyz="0.0" izz="1.0"/>
    </inertial>
  </link>
  <joint name="aero/boom_top_joint" type="fixed">
    <parent link="aero/boom"/>
    <child link="aero/boom_top"/>
    <origin rpy="0 0 0" xyz="0 0 1.085"/>
  </joint>
  <link name="aero/upper_stereo/camera_rail">
    <visual>
      <origin rpy="0 0 0" xyz="0 0 0.0127"/>
      <geometry>
        <box size="0.0508 0.26 0.0254"/>
      </geometry>
      <material name="Blue"/>
    </visual>
    <collision>
      <origin rpy="0 0 0" xyz="0 0 0.0127"/>
      <geometry>
        <box size="0.0508 0.26 0.0254"/>
      </geometry>
    </collision>
    <inertial>
      <origin rpy="0 0 0" xyz="0 0 0"/>
      <mass value="1"/>
      <inertia ixx="1.0" ixy="0.0" ixz="0.0" iyy="1.0" iyz="0.0" izz="1.0"/>
    </inertial>
  </link>
  <joint name="aero/upper_stereo/camera_rail_joint" type="fixed">
    <parent link="aero/boom_top"/>
    <child link="aero/upper_stereo/camera_rail"/>
    <origin rpy="0 0 0" xyz="0 0 0.005"/>
  </joint>
  <link name="aero/upper_stereo/camera_rail_tilt">
    <visual>
      <origin rpy="0 0 0" xyz="0 0 0"/>
      <geometry>
        <box size="0 0 0"/>
      </geometry>
    </visual>
    <collision>
      <origin rpy="0 0 0" xyz="0 0 0"/>
      <geometry>
        <box size="0 0 0"/>
      </geometry>
    </collision>
    <inertial>
      <origin rpy="0 0 0" xyz="0 0 0"/>
      <mass value="1"/>
      <inertia ixx="1.0" ixy="0.0" ixz="0.0" iyy="1.0" iyz="0.0" izz="1.0"/>
    </inertial>
  </link>
  <joint name="aero/upper_stereo/camera_rail_tilt_joint" type="fixed">
    <parent link="aero/upper_stereo/camera_rail"/>
    <child link="aero/upper_stereo/camera_rail_tilt"/>
    <origin rpy="0 0.209439510239 0" xyz="0 0 0.0127"/>
  </joint>
  <joint name="aero/upper_stereo/left_camera_frame_joint" type="fixed">
    <origin rpy="0 0 0" xyz="0.03 0.15 0.0227"/>
    <parent link="aero/upper_stereo/camera_rail_tilt"/>
    <child link="aero/upper_stereo/left_camera_frame"/>
  </joint>
  <link name="aero/upper_stereo/left_camera_frame">
    <visual>
      <origin rpy="0 0 0" xyz="0.0 0.0 0"/>
      <geometry>
        <mesh filename="package://aero_description/meshes/Manta-Camera-Lense.STL"/>
      </geometry>
    </visual>
    <inertial>
      <mass value="0.01"/>
      <origin rpy="0 0 0" xyz="0 0 0"/>
      <inertia ixx="0.001" ixy="0.0" ixz="0.0" iyy="0.001" iyz="0.0" izz="0.001"/>
    </inertial>
  </link>
  <joint name="aero/upper_stereo/left_camera_optical_frame_joint" type="fixed">
    <origin rpy="-1.57079632679 0 -1.57079632679" xyz="0 0 0"/>
    <parent link="aero/upper_stereo/left_camera_frame"/>
    <child link="aero/upper_stereo/left_camera_optical_frame"/>
  </joint>
  <link name="aero/upper_stereo/left_camera_optical_frame">
    <inertial>
      <mass value="0.01"/>
      <origin rpy="0 0 0" xyz="0 0 0"/>
      <inertia ixx="0.001" ixy="0.0" ixz="0.0" iyy="0.001" iyz="0.0" izz="0.001"/>
    </inertial>
  </link>
  <joint name="aero/upper_stereo/right_camera_frame_joint" type="fixed">
    <origin rpy="0 0 0" xyz="0.03 -0.15 0.0227"/>
    <parent link="aero/upper_stereo/camera_rail_tilt"/>
    <child link="aero/upper_stereo/right_camera_frame"/>
  </joint>
  <link name="aero/upper_stereo/right_camera_frame">
    <visual>
      <origin rpy="0 0 0" xyz="0.0 0.0 0"/>
      <geometry>
        <mesh filename="package://aero_description/meshes/Manta-Camera-Lense.STL"/>
      </geometry>
    </visual>
    <inertial>
      <mass value="0.01"/>
      <origin rpy="0 0 0" xyz="0 0 0"/>
      <inertia ixx="0.001" ixy="0.0" ixz="0.0" iyy="0.001" iyz="0.0" izz="0.001"/>
    </inertial>
  </link>
  <joint name="aero/upper_stereo/right_camera_optical_frame_joint" type="fixed">
    <origin rpy="-1.57079632679 0 -1.57079632679" xyz="0 0 0"/>
    <parent link="aero/upper_stereo/right_camera_frame"/>
    <child link="aero/upper_stereo/right_camera_optical_frame"/>
  </joint>
  <link name="aero/upper_stereo/right_camera_optical_frame">
    <inertial>
      <mass value="0.01"/>
      <origin rpy="0 0 0" xyz="0 0 0"/>
      <inertia ixx="0.001" ixy="0.0" ixz="0.0" iyy="0.001" iyz="0.0" izz="0.001"/>
    </inertial>
  </link>
  <link name="aero/upper_stereo/optical_frame">
    <visual>
      <geometry>
        <box size="0 0 0"/>
      </geometry>
      <material name="Clear">
        <color rgba="0 0 0 0"/>
      </material>
    </visual>
    <collision>
      <geometry>
        <box size="0 0 0"/>
      </geometry>
    </collision>
    <inertial>
      <origin rpy="0 0 0" xyz="0 0 0"/>
      <mass value="1"/>
      <inertia ixx="1.0" ixy="0.0" ixz="0.0" iyy="1.0" iyz="0.0" izz="1.0"/>
    </inertial>
  </link>
  <joint name="aero/upper_stereo/optical_frame_joint" type="fixed">
    <parent link="aero/upper_stereo/left_camera_optical_frame"/>
    <child link="aero/upper_stereo/optical_frame"/>
    <origin rpy="0 0 0" xyz="0 0 0.2534"/>
  </joint>
  <gazebo reference="aero/upper_stereo/camera_rail_tilt">
    <sensor name="aero/upper_stereo/camera" type="multicamera">
      <update_rate>30.0</update_rate>
      <camera name="left">
        <pose>0.06 0.15 0.0227 0 0 0</pose>
        <horizontal_fov>1.3962634</horizontal_fov>
        <image>
          <width>800</width>
          <height>800</height>
          <format>R8G8B8</format>
        </image>
        <clip>
          <near>0.02</near>
          <far>300</far>
        </clip>
        <noise>
          <type>gaussian</type>
          <mean>0.0</mean>
          <stddev>0.007</stddev>
        </noise>
      </camera>
      <camera name="right">
        <pose>0.06 -0.15 0.0227 0 0 0</pose>
        <horizontal_fov>1.3962634</horizontal_fov>
        <image>
          <width>800</width>
          <height>800</height>
          <format>R8G8B8</format>
        </image>
        <clip>
          <near>0.02</near>
          <far>300</far>
        </clip>
        <noise>
          <type>gaussian</type>
          <mean>0.0</mean>
          <stddev>0.007</stddev>
        </noise>
      </camera>
      <plugin filename="libgazebo_ros_multicamera.so" name="aero/upper_stereo/camera_controller">
        <alwaysOn>true</alwaysOn>
        <updateRate>0.0</updateRate>
        <cameraName>/aero/upper_stereo</cameraName>
        <imageTopicName>image_raw</imageTopicName>
        <cameraInfoTopicName>camera_info</cameraInfoTopicName>
        <frameName>aero/upper_stereo/optical_frame</frameName>
        <hackBaseline>0.07</hackBaseline>
        <distortionK1>0.0</distortionK1>
        <distortionK2>0.0</distortionK2>
        <distortionK3>0.0</distortionK3>
        <distortionT1>0.0</distortionT1>
        <distortionT2>0.0</distortionT2>
      </plugin>
    </sensor>
  </gazebo>
  <link name="aero/lower_stereo/camera_rail">
    <visual>
      <origin rpy="0 0 0" xyz="0 0 0.0127"/>
      <geometry>
        <box size="0.0508 0.07 0.0254"/>
      </geometry>
      <material name="Blue"/>
    </visual>
    <collision>
      <origin rpy="0 0 0" xyz="0 0 0.0127"/>
      <geometry>
        <box size="0.0508 0.07 0.0254"/>
      </geometry>
    </collision>
    <inertial>
      <origin rpy="0 0 0" xyz="0 0 0"/>
      <mass value="1"/>
      <inertia ixx="1.0" ixy="0.0" ixz="0.0" iyy="1.0" iyz="0.0" izz="1.0"/>
    </inertial>
  </link>
  <joint name="aero/lower_stereo/camera_rail_joint" type="fixed">
    <parent link="aero/boom_top"/>
    <child link="aero/lower_stereo/camera_rail"/>
    <origin rpy="0 0 0" xyz="0 0 -0.107"/>
  </joint>
  <link name="aero/lower_stereo/camera_rail_tilt">
    <visual>
      <origin rpy="0 0 0" xyz="0 0 0"/>
      <geometry>
        <box size="0 0 0"/>
      </geometry>
    </visual>
    <collision>
      <origin rpy="0 0 0" xyz="0 0 0"/>
      <geometry>
        <box size="0 0 0"/>
      </geometry>
    </collision>
    <inertial>
      <origin rpy="0 0 0" xyz="0 0 0"/>
      <mass value="1"/>
      <inertia ixx="1.0" ixy="0.0" ixz="0.0" iyy="1.0" iyz="0.0" izz="1.0"/>
    </inertial>
  </link>
  <joint name="aero/lower_stereo/camera_rail_tilt_joint" type="fixed">
    <parent link="aero/lower_stereo/camera_rail"/>
    <child link="aero/lower_stereo/camera_rail_tilt"/>
    <origin rpy="0 0.628318530718 0" xyz="0 0 0.0127"/>
  </joint>
  <joint name="aero/lower_stereo/left_camera_frame_joint" type="fixed">
    <origin rpy="0 0 0" xyz="0.03 0.055 0.0227"/>
    <parent link="aero/lower_stereo/camera_rail_tilt"/>
    <child link="aero/lower_stereo/left_camera_frame"/>
  </joint>
  <link name="aero/lower_stereo/left_camera_frame">
    <visual>
      <origin rpy="0 0 0" xyz="0.0 0.0 0"/>
      <geometry>
        <mesh filename="package://aero_description/meshes/Manta-Camera-Lense.STL"/>
      </geometry>
    </visual>
    <inertial>
      <mass value="0.01"/>
      <origin rpy="0 0 0" xyz="0 0 0"/>
      <inertia ixx="0.001" ixy="0.0" ixz="0.0" iyy="0.001" iyz="0.0" izz="0.001"/>
    </inertial>
  </link>
  <joint name="aero/lower_stereo/left_camera_optical_frame_joint" type="fixed">
    <origin rpy="-1.57079632679 0 -1.57079632679" xyz="0 0 0"/>
    <parent link="aero/lower_stereo/left_camera_frame"/>
    <child link="aero/lower_stereo/left_camera_optical_frame"/>
  </joint>
  <link name="aero/lower_stereo/left_camera_optical_frame">
    <inertial>
      <mass value="0.01"/>
      <origin rpy="0 0 0" xyz="0 0 0"/>
      <inertia ixx="0.001" ixy="0.0" ixz="0.0" iyy="0.001" iyz="0.0" izz="0.001"/>
    </inertial>
  </link>
  <joint name="aero/lower_stereo/right_camera_frame_joint" type="fixed">
    <origin rpy="0 0 0" xyz="0.03 -0.055 0.0227"/>
    <parent link="aero/lower_stereo/camera_rail_tilt"/>
    <child link="aero/lower_stereo/right_camera_frame"/>
  </joint>
  <link name="aero/lower_stereo/right_camera_frame">
    <visual>
      <origin rpy="0 0 0" xyz="0.0 0.0 0"/>
      <geometry>
        <mesh filename="package://aero_description/meshes/Manta-Camera-Lense.STL"/>
      </geometry>
    </visual>
    <inertial>
      <mass value="0.01"/>
      <origin rpy="0 0 0" xyz="0 0 0"/>
      <inertia ixx="0.001" ixy="0.0" ixz="0.0" iyy="0.001" iyz="0.0" izz="0.001"/>
    </inertial>
  </link>
  <joint name="aero/lower_stereo/right_camera_optical_frame_joint" type="fixed">
    <origin rpy="-1.57079632679 0 -1.57079632679" xyz="0 0 0"/>
    <parent link="aero/lower_stereo/right_camera_frame"/>
    <child link="aero/lower_stereo/right_camera_optical_frame"/>
  </joint>
  <link name="aero/lower_stereo/right_camera_optical_frame">
    <inertial>
      <mass value="0.01"/>
      <origin rpy="0 0 0" xyz="0 0 0"/>
      <inertia ixx="0.001" ixy="0.0" ixz="0.0" iyy="0.001" iyz="0.0" izz="0.001"/>
    </inertial>
  </link>
  <link name="aero/lower_stereo/optical_frame">
    <visual>
      <geometry>
        <box size="0 0 0"/>
      </geometry>
      <material name="Clear">
        <color rgba="0 0 0 0"/>
      </material>
    </visual>
    <collision>
      <geometry>
        <box size="0 0 0"/>
      </geometry>
    </collision>
    <inertial>
      <origin rpy="0 0 0" xyz="0 0 0"/>
      <mass value="1"/>
      <inertia ixx="1.0" ixy="0.0" ixz="0.0" iyy="1.0" iyz="0.0" izz="1.0"/>
    </inertial>
  </link>
  <joint name="aero/lower_stereo/optical_frame_joint" type="fixed">
    <parent link="aero/lower_stereo/left_camera_optical_frame"/>
    <child link="aero/lower_stereo/optical_frame"/>
    <origin rpy="0 0 0" xyz="0 0 0.11"/>
  </joint>
  <gazebo reference="aero/lower_stereo/camera_rail_tilt">
    <sensor name="aero/lower_stereo/camera" type="multicamera">
      <update_rate>30.0</update_rate>
      <camera name="left">
        <pose>0.06 0.055 0.0227 0 0 0</pose>
        <horizontal_fov>1.3962634</horizontal_fov>
        <image>
          <width>800</width>
          <height>800</height>
          <format>R8G8B8</format>
        </image>
        <clip>
          <near>0.02</near>
          <far>300</far>
        </clip>
        <noise>
          <type>gaussian</type>
          <mean>0.0</mean>
          <stddev>0.007</stddev>
        </noise>
      </camera>
      <camera name="right">
        <pose>0.06 -0.055 0.0227 0 0 0</pose>
        <horizontal_fov>1.3962634</horizontal_fov>
        <image>
          <width>800</width>
          <height>800</height>
          <format>R8G8B8</format>
        </image>
        <clip>
          <near>0.02</near>
          <far>300</far>
        </clip>
        <noise>
          <type>gaussian</type>
          <mean>0.0</mean>
          <stddev>0.007</stddev>
        </noise>
      </camera>
      <plugin filename="libgazebo_ros_multicamera.so" name="aero/lower_stereo/camera_controller">
        <alwaysOn>true</alwaysOn>
        <updateRate>0.0</updateRate>
        <cameraName>/aero/lower_stereo</cameraName>
        <imageTopicName>image_raw</imageTopicName>
        <cameraInfoTopicName>camera_info</cameraInfoTopicName>
        <frameName>aero/lower_stereo/optical_frame</frameName>
        <hackBaseline>0.07</hackBaseline>
        <distortionK1>0.0</distortionK1>
        <distortionK2>0.0</distortionK2>
        <distortionK3>0.0</distortionK3>
        <distortionT1>0.0</distortionT1>
        <distortionT2>0.0</distortionT2>
      </plugin>
    </sensor>
  </gazebo>
  <link name="aero/boom_base">
    <visual>
      <origin rpy="0 0 0" xyz="0 0 -0.02"/>
      <geometry>
        <box size="0.05 0.05 0.05"/>
      </geometry>
      <material name="Blue"/>
    </visual>
    <collision>
      <origin rpy="0 0 0" xyz="0 0 -0.02"/>
      <geometry>
        <box size="0.05 0.05 0.05"/>
      </geometry>
    </collision>
    <inertial>
      <origin rpy="0 0 0" xyz="0 0 0"/>
      <mass value="1"/>
      <inertia ixx="1.0" ixy="0.0" ixz="0.0" iyy="1.0" iyz="0.0" izz="1.0"/>
    </inertial>
  </link>
  <joint name="aero/boom_base_joint" type="fixed">
    <parent link="aero/base_footprint"/>
    <child link="aero/boom_base"/>
    <origin rpy="0 0 0" xyz="-0.4191 0 0.28575"/>
  </joint>
  <!-- IMU -->
  <!--<xacro:static_transform parent="${robot_ns}/base_link" name="${robot_ns}/imu" xyz="0 0 0" rpy="0 ${-M_PI/2} ${-3*M_PI/4}">-->
  <link name="aero/imu">
    <collision>
      <origin rpy="0 0 0" xyz="0 0 0"/>
      <geometry>
        <box size="0.01 0.01 0.01"/>
      </geometry>
    </collision>
    <visual>
      <origin rpy="0 0 0" xyz="0 0 0"/>
      <geometry>
        <box size="0.01 0.01 0.01"/>
      </geometry>
      <material name="Blue"/>
    </visual>
    <inertial>
      <origin rpy="0 0 0" xyz="0 0 0"/>
      <mass value="1"/>
      <inertia ixx="1.0" ixy="0.0" ixz="0.0" iyy="1.0" iyz="0.0" izz="1.0"/>
    </inertial>
  </link>
  <joint name="aero/imu_joint" type="fixed">
    <parent link="aero/base_link"/>
    <child link="aero/imu"/>
    <origin rpy="0 0 0" xyz="0 0 0"/>
  </joint>
  <!-- Arm Base -->
  <link name="aero/arm_mount">
    <collision>
      <origin rpy="0 0 0" xyz="0 0 0"/>
      <geometry>
        <box size="0.01 0.01 0.01"/>
      </geometry>
    </collision>
    <visual>
      <origin rpy="0 0 0" xyz="0 0 0"/>
      <geometry>
        <box size="0.01 0.01 0.01"/>
      </geometry>
      <material name="Blue"/>
    </visual>
    <inertial>
      <origin rpy="0 0 0" xyz="0 0 0"/>
      <mass value="1"/>
      <inertia ixx="1.0" ixy="0.0" ixz="0.0" iyy="1.0" iyz="0.0" izz="1.0"/>
    </inertial>
  </link>
  <joint name="aero/arm_mount_joint" type="fixed">
    <parent link="aero/base_link"/>
    <child link="aero/arm_mount"/>
    <origin rpy="0 0 1.57079632679" xyz="0.323 0 0"/>
  </joint>
  <link name="arm_base">
    <collision>
      <origin rpy="0 0 0" xyz="0 0 0"/>
      <geometry>
        <box size="0.01 0.01 0.01"/>
      </geometry>
    </collision>
    <visual>
      <origin rpy="0 0 0" xyz="0 0 0"/>
      <geometry>
        <box size="0.01 0.01 0.01"/>
      </geometry>
      <material name="Blue"/>
    </visual>
    <inertial>
      <origin rpy="0 0 0" xyz="0 0 0"/>
      <mass value="1"/>
      <inertia ixx="1.0" ixy="0.0" ixz="0.0" iyy="1.0" iyz="0.0" izz="1.0"/>
    </inertial>
  </link>
  <joint name="arm_base_joint" type="fixed">
    <parent link="aero/arm_mount"/>
    <child link="arm_base"/>
    <origin rpy="0 0 -1.57079632679" xyz="0 0 0"/>
  </joint>
  <link name="jaco_link_base">
    <visual>
      <geometry>
        <mesh filename="package://jaco_model/meshes/jaco_link_base.dae"/>
      </geometry>
      <material name="carbon_fiber">
        <color rgba="0.792156862745098 0.819607843137255 0.933333333333333 1"/>
      </material>
    </visual>
    <collision>
      <geometry>
        <mesh filename="package://jaco_model/meshes/jaco_link_base.dae"/>
      </geometry>
    </collision>
  </link>
  <joint name="jaco_joint_base" type="fixed">
    <parent link="arm_base"/>
    <child link="jaco_link_base"/>
    <axis xyz="0 0 0"/>
    <origin rpy="0 0 0" xyz="0 0 0"/>
    <limit effort="30" lower="-6.28318530718" upper="6.28318530718" velocity="5"/>
  </joint>
  <link name="jaco_link_1">
    <visual>
      <geometry>
        <mesh filename="package://jaco_model/meshes/jaco_link_1.dae"/>
      </geometry>
      <material name="carbon_fiber">
        <color rgba="0.792156862745098 0.819607843137255 0.933333333333333 1"/>
      </material>
    </visual>
    <collision>
      <geometry>
        <mesh filename="package://jaco_model/meshes/jaco_link_1.dae"/>
      </geometry>
    </collision>
  </link>
  <joint name="jaco_joint_1" type="revolute">
    <parent link="jaco_link_base"/>
    <child link="jaco_link_1"/>
    <axis xyz="0 0 1"/>
    <origin rpy="3.14159265359 0 0" xyz="0 0 0.1535"/>
    <limit effort="30" lower="-6.28318530718" upper="6.28318530718" velocity="5"/>
  </joint>
  <link name="jaco_link_2">
    <visual>
      <geometry>
        <mesh filename="package://jaco_model/meshes/jaco_link_2.dae"/>
      </geometry>
      <material name="carbon_fiber">
        <color rgba="0.792156862745098 0.819607843137255 0.933333333333333 1"/>
      </material>
    </visual>
    <collision>
      <geometry>
        <mesh filename="package://jaco_model/meshes/jaco_link_2.dae"/>
      </geometry>
    </collision>
  </link>
  <joint name="jaco_joint_2" type="revolute">
    <parent link="jaco_link_1"/>
    <child link="jaco_link_2"/>
    <axis xyz="0 0 1"/>
    <origin rpy="-1.57079632679 -1.57079632679 0" xyz="0 0 -0.1185"/>
    <limit effort="30" lower="0" upper="6.28318530718" velocity="5"/>
  </joint>
  <link name="jaco_link_3">
    <visual>
      <geometry>
        <mesh filename="package://jaco_model/meshes/jaco_link_3.dae"/>
      </geometry>
      <material name="carbon_fiber">
        <color rgba="0.792156862745098 0.819607843137255 0.933333333333333 1"/>
      </material>
    </visual>
    <collision>
      <geometry>
        <mesh filename="package://jaco_model/meshes/jaco_link_3.dae"/>
      </geometry>
    </collision>
  </link>
  <joint name="jaco_joint_3" type="revolute">
    <parent link="jaco_link_2"/>
    <child link="jaco_link_3"/>
    <axis xyz="0 0 1"/>
    <origin rpy="3.14159265359 0 3.14159265359" xyz="0.41 0 0"/>
    <limit effort="30" lower="0" upper="6.28318530718" velocity="5"/>
  </joint>
  <link name="jaco_link_4">
    <visual>
      <geometry>
        <mesh filename="package://jaco_model/meshes/jaco_link_4.dae"/>
      </geometry>
      <material name="carbon_fiber">
        <color rgba="0.792156862745098 0.819607843137255 0.933333333333333 1"/>
      </material>
    </visual>
    <collision>
      <geometry>
        <mesh filename="package://jaco_model/meshes/jaco_link_4.dae"/>
      </geometry>
    </collision>
  </link>
  <joint name="jaco_joint_4" type="revolute">
    <parent link="jaco_link_3"/>
    <child link="jaco_link_4"/>
    <axis xyz="0 0 1"/>
    <origin rpy="0 -1.57079632679 0" xyz="0.207 0 -0.01125"/>
    <limit effort="30" lower="-6.28318530718" upper="6.28318530718" velocity="5"/>
  </joint>
  <link name="jaco_link_5">
    <visual>
      <geometry>
        <mesh filename="package://jaco_model/meshes/jaco_link_5.dae"/>
      </geometry>
      <material name="carbon_fiber">
        <color rgba="0.792156862745098 0.819607843137255 0.933333333333333 1"/>
      </material>
    </visual>
    <collision>
      <geometry>
        <mesh filename="package://jaco_model/meshes/jaco_link_5.dae"/>
      </geometry>
    </collision>
  </link>
  <joint name="jaco_joint_5" type="revolute">
    <parent link="jaco_link_4"/>
    <child link="jaco_link_5"/>
    <axis xyz="0 0 1"/>
    <origin rpy="0 0.959931088597 3.14159265359" xyz="0.0343 0 -0.06588"/>
    <limit effort="30" lower="-6.28318530718" upper="6.28318530718" velocity="5"/>
  </joint>
  <link name="jaco_link_hand">
    <visual>
      <geometry>
        <mesh filename="package://jaco_model/meshes/jaco_link_hand.dae"/>
      </geometry>
      <material name="carbon_fiber">
        <color rgba="0.792156862745098 0.819607843137255 0.933333333333333 1"/>
      </material>
    </visual>
    <collision>
      <geometry>
        <mesh filename="package://jaco_model/meshes/jaco_link_hand.dae"/>
      </geometry>
    </collision>
  </link>
  <joint name="jaco_joint_6" type="revolute">
    <parent link="jaco_link_5"/>
    <child link="jaco_link_hand"/>
    <axis xyz="0 0 1"/>
    <origin rpy="0 0.959931088597 3.14159265359" xyz="0.0343 0 -0.06588"/>
    <limit effort="30" lower="-6.28318530718" upper="6.28318530718" velocity="5"/>
  </joint>
  <link name="jaco_link_finger_1">
    <visual>
      <geometry>
        <mesh filename="package://jaco_model/meshes/jaco_link_finger_1.dae"/>
      </geometry>
      <material name="carbon_fiber">
        <color rgba="0.792156862745098 0.819607843137255 0.933333333333333 1"/>
      </material>
    </visual>
    <collision>
      <geometry>
        <mesh filename="package://jaco_model/meshes/jaco_link_finger_1.dae"/>
      </geometry>
    </collision>
  </link>
  <joint name="jaco_joint_finger_1" type="revolute">
    <parent link="jaco_link_hand"/>
    <child link="jaco_link_finger_1"/>
    <axis xyz="0 0 1"/>
    <origin rpy="-1.7983 1.117 3.1416" xyz="-0.03978 0 -0.10071"/>
    <limit effort="30" lower="0" upper="0.698131700798" velocity="5"/>
  </joint>
  <link name="jaco_link_finger_2">
    <visual>
      <geometry>
        <mesh filename="package://jaco_model/meshes/jaco_link_finger_2.dae"/>
      </geometry>
      <material name="carbon_fiber">
        <color rgba="0.792156862745098 0.819607843137255 0.933333333333333 1"/>
      </material>
    </visual>
    <collision>
      <geometry>
        <mesh filename="package://jaco_model/meshes/jaco_link_finger_2.dae"/>
      </geometry>
    </collision>
  </link>
  <joint name="jaco_joint_finger_2" type="revolute">
    <parent link="jaco_link_hand"/>
    <child link="jaco_link_finger_2"/>
    <axis xyz="0 0 1"/>
    <origin rpy="-1.6222 1.117 -0.23615" xyz="0.03569 -0.0216 -0.10071"/>
    <limit effort="30" lower="0" upper="0.698131700798" velocity="5"/>
  </joint>
  <link name="jaco_link_finger_3">
    <visual>
      <geometry>
        <mesh filename="package://jaco_model/meshes/jaco_link_finger_3.dae"/>
      </geometry>
      <material name="carbon_fiber">
        <color rgba="0.792156862745098 0.819607843137255 0.933333333333333 1"/>
      </material>
    </visual>
    <collision>
      <geometry>
        <mesh filename="package://jaco_model/meshes/jaco_link_finger_3.dae"/>
      </geometry>
    </collision>
  </link>
  <joint name="jaco_joint_finger_3" type="revolute">
    <parent link="jaco_link_hand"/>
    <child link="jaco_link_finger_3"/>
    <axis xyz="0 0 1"/>
    <origin rpy="-1.5161 1.1459 0.23978" xyz="0.03569 0.0216 -0.10071"/>
    <limit effort="30" lower="0" upper="0.698131700798" velocity="5"/>
  </joint>
  <gazebo reference="aero/imu">
    <sensor name="imu_sensor" type="imu">
      <!--from atlas-->
      <always_on>1</always_on>
      <update_rate>1000.0</update_rate>
      <imu>
        <noise>
          <type>gaussian</type>
          <!-- Noise parameters from Boston Dynamics
	       (http://gazebosim.org/wiki/Sensor_noise):
	       rates (rad/s): mean=0, stddev=2e-4
	       accels (m/s/s): mean=0, stddev=1.7e-2
	       rate bias (rad/s): 5e-6 - 1e-5
	       accel bias (m/s/s): 1e-1
	       Experimentally, simulation provide rates with noise of
	       about 1e-3 rad/s and accels with noise of about 1e-1 m/s/s.
	       So we don't expect to see the noise unless number of inner iterations
	       are increased.

We will add bias.  In this model, bias is sampled once for rates
and once for accels at startup; the sign (negative or positive)
of each bias is then switched with equal probability.  Thereafter,
the biases are fixed additive offsets.  We choose
bias means and stddevs to produce biases close to the provided
data. -->
          <rate>
            <mean>0.0</mean>
            <stddev>2e-4</stddev>
            <bias_mean>0.0000075</bias_mean>
            <bias_stddev>0.0000008</bias_stddev>
          </rate>
          <accel>
            <mean>0.0</mean>
            <stddev>1.7e-2</stddev>
            <bias_mean>0.1</bias_mean>
            <bias_stddev>0.001</bias_stddev>
          </accel>
        </noise>
      </imu>
    </sensor>
  </gazebo>
  <gazebo>
    <!-- need to put it in it's own gazebo tag with no reference because the imu plugin is a model plugin -->
    <plugin filename="libgazebo_ros_imu.so" name="imu_controller">
      <bodyName>aero/imu</bodyName>
      <robotNamespace>/aero</robotNamespace>
      <topicName>imu/data</topicName>
      <serviceName>imu/calibrate</serviceName>
      <gaussianNoise>0.0</gaussianNoise>
      <!--TODO determine what this parameter is -->
    </plugin>
  </gazebo>
</robot>

